     ERROR   Exception in ASGI application
Traceback (most recent call last):
  File "/Users/gohilsuryadeepsinh/Desktop/tic-tech-toe/python-backend/.venv/lib/python3.13/site-packages/uvicorn/protocols/http/httptools_impl.py", line 409, in run_asgi
    result = await app(  # type: ignore[func-returns-value]
             ^^^^^^^^^^^^^^^^^^^^^^^^^^^^^^^^^^^^^^^^^^^^^^
        self.scope, self.receive, self.send
        ^^^^^^^^^^^^^^^^^^^^^^^^^^^^^^^^^^^
    )
    ^
  File "/Users/gohilsuryadeepsinh/Desktop/tic-tech-toe/python-backend/.venv/lib/python3.13/site-packages/uvicorn/middleware/proxy_headers.py", line 60, in __call__
    return await self.app(scope, receive, send)
           ^^^^^^^^^^^^^^^^^^^^^^^^^^^^^^^^^^^^
  File "/Users/gohilsuryadeepsinh/Desktop/tic-tech-toe/python-backend/.venv/lib/python3.13/site-packages/fastapi/applications.py", line 1054, in __call__
    await super().__call__(scope, receive, send)
  File "/Users/gohilsuryadeepsinh/Desktop/tic-tech-toe/python-backend/.venv/lib/python3.13/site-packages/starlette/applications.py", line 112, in __call__
    await self.middleware_stack(scope, receive, send)
  File "/Users/gohilsuryadeepsinh/Desktop/tic-tech-toe/python-backend/.venv/lib/python3.13/site-packages/starlette/middleware/errors.py", line 187, in __call__
    raise exc
  File "/Users/gohilsuryadeepsinh/Desktop/tic-tech-toe/python-backend/.venv/lib/python3.13/site-packages/starlette/middleware/errors.py", line 165, in __call__
    await self.app(scope, receive, _send)
  File "/Users/gohilsuryadeepsinh/Desktop/tic-tech-toe/python-backend/.venv/lib/python3.13/site-packages/starlette/middleware/cors.py", line 93, in __call__
    await self.simple_response(scope, receive, send, request_headers=headers)
  File "/Users/gohilsuryadeepsinh/Desktop/tic-tech-toe/python-backend/.venv/lib/python3.13/site-packages/starlette/middleware/cors.py", line 144, in simple_response
    await self.app(scope, receive, send)
  File "/Users/gohilsuryadeepsinh/Desktop/tic-tech-toe/python-backend/.venv/lib/python3.13/site-packages/starlette/middleware/exceptions.py", line 62, in __call__
    await wrap_app_handling_exceptions(self.app, conn)(scope, receive, send)
  File "/Users/gohilsuryadeepsinh/Desktop/tic-tech-toe/python-backend/.venv/lib/python3.13/site-packages/starlette/_exception_handler.py", line 53, in wrapped_app
    raise exc
  File "/Users/gohilsuryadeepsinh/Desktop/tic-tech-toe/python-backend/.venv/lib/python3.13/site-packages/starlette/_exception_handler.py", line 42, in wrapped_app
    await app(scope, receive, sender)
  File "/Users/gohilsuryadeepsinh/Desktop/tic-tech-toe/python-backend/.venv/lib/python3.13/site-packages/starlette/routing.py", line 714, in __call__
    await self.middleware_stack(scope, receive, send)
  File "/Users/gohilsuryadeepsinh/Desktop/tic-tech-toe/python-backend/.venv/lib/python3.13/site-packages/starlette/routing.py", line 734, in app
    await route.handle(scope, receive, send)
  File "/Users/gohilsuryadeepsinh/Desktop/tic-tech-toe/python-backend/.venv/lib/python3.13/site-packages/starlette/routing.py", line 288, in handle
    await self.app(scope, receive, send)
  File "/Users/gohilsuryadeepsinh/Desktop/tic-tech-toe/python-backend/.venv/lib/python3.13/site-packages/starlette/routing.py", line 76, in app
    await wrap_app_handling_exceptions(app, request)(scope, receive, send)
  File "/Users/gohilsuryadeepsinh/Desktop/tic-tech-toe/python-backend/.venv/lib/python3.13/site-packages/starlette/_exception_handler.py", line 53, in wrapped_app
    raise exc
  File "/Users/gohilsuryadeepsinh/Desktop/tic-tech-toe/python-backend/.venv/lib/python3.13/site-packages/starlette/_exception_handler.py", line 42, in wrapped_app
    await app(scope, receive, sender)
  File "/Users/gohilsuryadeepsinh/Desktop/tic-tech-toe/python-backend/.venv/lib/python3.13/site-packages/starlette/routing.py", line 73, in app
    response = await f(request)
               ^^^^^^^^^^^^^^^^
  File "/Users/gohilsuryadeepsinh/Desktop/tic-tech-toe/python-backend/.venv/lib/python3.13/site-packages/fastapi/routing.py", line 301, in app
    raw_response = await run_endpoint_function(
                   ^^^^^^^^^^^^^^^^^^^^^^^^^^^^
    ...<3 lines>...
    )
    ^
  File "/Users/gohilsuryadeepsinh/Desktop/tic-tech-toe/python-backend/.venv/lib/python3.13/site-packages/fastapi/routing.py", line 212, in run_endpoint_function
    return await dependant.call(**values)
           ^^^^^^^^^^^^^^^^^^^^^^^^^^^^^^
  File "/Users/gohilsuryadeepsinh/Desktop/tic-tech-toe/python-backend/main.py", line 182, in verify_certificate
    text = extract_text_from_image(contents)
  File "/Users/gohilsuryadeepsinh/Desktop/tic-tech-toe/python-backend/main.py", line 153, in extract_text_from_image
    results = ocr.ocr(image_cv, cls=True)
  File "/Users/gohilsuryadeepsinh/Desktop/tic-tech-toe/python-backend/.venv/lib/python3.13/site-packages/paddleocr/paddleocr.py", line 766, in ocr
    dt_boxes, rec_res, _ = self.__call__(img, cls, slice)
                           ~~~~~~~~~~~~~^^^^^^^^^^^^^^^^^
  File "/Users/gohilsuryadeepsinh/Desktop/tic-tech-toe/python-backend/.venv/lib/python3.13/site-packages/paddleocr/tools/infer/predict_system.py", line 144, in __call__
    rec_res, elapse = self.text_recognizer(img_crop_list)
                      ~~~~~~~~~~~~~~~~~~~~^^^^^^^^^^^^^^^
  File "/Users/gohilsuryadeepsinh/Desktop/tic-tech-toe/python-backend/.venv/lib/python3.13/site-packages/paddleocr/tools/infer/predict_rec.py", line 793, in __call__
    self.predictor.run()
    ~~~~~~~~~~~~~~~~~~^^
RuntimeError: (NotFound) No allocator found for the place, Place(undefined:0)
  [Hint: Expected iter != allocators.end(), but received iter == allocators.end().] (at /Users/paddle/xly/workspace/7b5bf7ed-f223-4c37-9311-a1c9d604457b/Paddle/paddle/phi/core/memory/allocation/allocator_facade.cc:381)
  [operator < matmul > error]
[2025-04-14 16:59:35,523] [   ERROR] httptools_impl.py:414 - Exception in ASGI application
Traceback (most recent call last):
  File "/Users/gohilsuryadeepsinh/Desktop/tic-tech-toe/python-backend/.venv/lib/python3.13/site-packages/uvicorn/protocols/http/httptools_impl.py", line 409, in run_asgi
    result = await app(  # type: ignore[func-returns-value]
             ^^^^^^^^^^^^^^^^^^^^^^^^^^^^^^^^^^^^^^^^^^^^^^
        self.scope, self.receive, self.send
        ^^^^^^^^^^^^^^^^^^^^^^^^^^^^^^^^^^^
    )
    ^
  File "/Users/gohilsuryadeepsinh/Desktop/tic-tech-toe/python-backend/.venv/lib/python3.13/site-packages/uvicorn/middleware/proxy_headers.py", line 60, in __call__
    return await self.app(scope, receive, send)
           ^^^^^^^^^^^^^^^^^^^^^^^^^^^^^^^^^^^^
  File "/Users/gohilsuryadeepsinh/Desktop/tic-tech-toe/python-backend/.venv/lib/python3.13/site-packages/fastapi/applications.py", line 1054, in __call__
    await super().__call__(scope, receive, send)
  File "/Users/gohilsuryadeepsinh/Desktop/tic-tech-toe/python-backend/.venv/lib/python3.13/site-packages/starlette/applications.py", line 112, in __call__
    await self.middleware_stack(scope, receive, send)
  File "/Users/gohilsuryadeepsinh/Desktop/tic-tech-toe/python-backend/.venv/lib/python3.13/site-packages/starlette/middleware/errors.py", line 187, in __call__
    raise exc
  File "/Users/gohilsuryadeepsinh/Desktop/tic-tech-toe/python-backend/.venv/lib/python3.13/site-packages/starlette/middleware/errors.py", line 165, in __call__
    await self.app(scope, receive, _send)
  File "/Users/gohilsuryadeepsinh/Desktop/tic-tech-toe/python-backend/.venv/lib/python3.13/site-packages/starlette/middleware/cors.py", line 93, in __call__
    await self.simple_response(scope, receive, send, request_headers=headers)
  File "/Users/gohilsuryadeepsinh/Desktop/tic-tech-toe/python-backend/.venv/lib/python3.13/site-packages/starlette/middleware/cors.py", line 144, in simple_response
    await self.app(scope, receive, send)
  File "/Users/gohilsuryadeepsinh/Desktop/tic-tech-toe/python-backend/.venv/lib/python3.13/site-packages/starlette/middleware/exceptions.py", line 62, in __call__
    await wrap_app_handling_exceptions(self.app, conn)(scope, receive, send)
  File "/Users/gohilsuryadeepsinh/Desktop/tic-tech-toe/python-backend/.venv/lib/python3.13/site-packages/starlette/_exception_handler.py", line 53, in wrapped_app
    raise exc
  File "/Users/gohilsuryadeepsinh/Desktop/tic-tech-toe/python-backend/.venv/lib/python3.13/site-packages/starlette/_exception_handler.py", line 42, in wrapped_app
    await app(scope, receive, sender)
  File "/Users/gohilsuryadeepsinh/Desktop/tic-tech-toe/python-backend/.venv/lib/python3.13/site-packages/starlette/routing.py", line 714, in __call__
    await self.middleware_stack(scope, receive, send)
  File "/Users/gohilsuryadeepsinh/Desktop/tic-tech-toe/python-backend/.venv/lib/python3.13/site-packages/starlette/routing.py", line 734, in app
    await route.handle(scope, receive, send)
  File "/Users/gohilsuryadeepsinh/Desktop/tic-tech-toe/python-backend/.venv/lib/python3.13/site-packages/starlette/routing.py", line 288, in handle
    await self.app(scope, receive, send)
  File "/Users/gohilsuryadeepsinh/Desktop/tic-tech-toe/python-backend/.venv/lib/python3.13/site-packages/starlette/routing.py", line 76, in app
    await wrap_app_handling_exceptions(app, request)(scope, receive, send)
  File "/Users/gohilsuryadeepsinh/Desktop/tic-tech-toe/python-backend/.venv/lib/python3.13/site-packages/starlette/_exception_handler.py", line 53, in wrapped_app
    raise exc
  File "/Users/gohilsuryadeepsinh/Desktop/tic-tech-toe/python-backend/.venv/lib/python3.13/site-packages/starlette/_exception_handler.py", line 42, in wrapped_app
    await app(scope, receive, sender)
  File "/Users/gohilsuryadeepsinh/Desktop/tic-tech-toe/python-backend/.venv/lib/python3.13/site-packages/starlette/routing.py", line 73, in app
    response = await f(request)
               ^^^^^^^^^^^^^^^^
  File "/Users/gohilsuryadeepsinh/Desktop/tic-tech-toe/python-backend/.venv/lib/python3.13/site-packages/fastapi/routing.py", line 301, in app
    raw_response = await run_endpoint_function(
                   ^^^^^^^^^^^^^^^^^^^^^^^^^^^^
    ...<3 lines>...
    )
    ^
  File "/Users/gohilsuryadeepsinh/Desktop/tic-tech-toe/python-backend/.venv/lib/python3.13/site-packages/fastapi/routing.py", line 212, in run_endpoint_function
    return await dependant.call(**values)
           ^^^^^^^^^^^^^^^^^^^^^^^^^^^^^^
  File "/Users/gohilsuryadeepsinh/Desktop/tic-tech-toe/python-backend/main.py", line 182, in verify_certificate
    text = extract_text_from_image(contents)
  File "/Users/gohilsuryadeepsinh/Desktop/tic-tech-toe/python-backend/main.py", line 153, in extract_text_from_image
    results = ocr.ocr(image_cv, cls=True)
  File "/Users/gohilsuryadeepsinh/Desktop/tic-tech-toe/python-backend/.venv/lib/python3.13/site-packages/paddleocr/paddleocr.py", line 766, in ocr
    dt_boxes, rec_res, _ = self.__call__(img, cls, slice)
                           ~~~~~~~~~~~~~^^^^^^^^^^^^^^^^^
  File "/Users/gohilsuryadeepsinh/Desktop/tic-tech-toe/python-backend/.venv/lib/python3.13/site-packages/paddleocr/tools/infer/predict_system.py", line 144, in __call__
    rec_res, elapse = self.text_recognizer(img_crop_list)
                      ~~~~~~~~~~~~~~~~~~~~^^^^^^^^^^^^^^^
  File "/Users/gohilsuryadeepsinh/Desktop/tic-tech-toe/python-backend/.venv/lib/python3.13/site-packages/paddleocr/tools/infer/predict_rec.py", line 793, in __call__
    self.predictor.run()
    ~~~~~~~~~~~~~~~~~~^^
RuntimeError: (NotFound) No allocator found for the place, Place(undefined:0)
  [Hint: Expected iter != allocators.end(), but received iter == allocators.end().] (at /Users/paddle/xly/workspace/7b5bf7ed-f223-4c37-9311-a1c9d604457b/Paddle/paddle/phi/core/memory/allocation/allocator_facade.cc:381)